Failure # 1 (occurred at 2023-10-08_12-20-24)
The actor died because of an error raised in its creation task, [36mray::PPO.__init__()[39m (pid=21935, ip=127.0.0.1, actor_id=9512c01709e66983e0ddaa4e01000000, repr=PPO)
  File "/Users/jakejones/.virtualenvs/pettingzoo/lib/python3.11/site-packages/ray/rllib/evaluation/worker_set.py", line 227, in _setup
    self.add_workers(
  File "/Users/jakejones/.virtualenvs/pettingzoo/lib/python3.11/site-packages/ray/rllib/evaluation/worker_set.py", line 593, in add_workers
    raise result.get()
  File "/Users/jakejones/.virtualenvs/pettingzoo/lib/python3.11/site-packages/ray/rllib/utils/actor_manager.py", line 481, in __fetch_result
    result = ray.get(r)
             ^^^^^^^^^^
           ^^^^^^^^^^^^^^^^^^^
           ^^^^^^^^^^^^^^^^^^^^^
ray.exceptions.RayActorError: The actor died because of an error raised in its creation task, [36mray::RolloutWorker.__init__()[39m (pid=21943, ip=127.0.0.1, actor_id=96eb5048dfa308471bcaccc301000000, repr=<ray.rllib.evaluation.rollout_worker.RolloutWorker object at 0x105e46a50>)
  File "/Users/jakejones/.virtualenvs/pettingzoo/lib/python3.11/site-packages/ray/rllib/utils/pre_checks/env.py", line 320, in check_multiagent_environments
    _check_if_element_multi_agent_dict(env, reset_obs, "reset()")
  File "/Users/jakejones/.virtualenvs/pettingzoo/lib/python3.11/site-packages/ray/rllib/utils/pre_checks/env.py", line 785, in _check_if_element_multi_agent_dict
    raise ValueError(error)
ValueError: The element returned by reset() has agent_ids that are not the names of the agents in the env. 
Agent_ids in this MultiAgentDict: ['player_0', 'player_1']
Agent_ids in this env:[]. You likely need to add the private attribute `_agent_ids` to your env, which is a set containing the ids of agents supported by your env.

During handling of the above exception, another exception occurred:

[36mray::RolloutWorker.__init__()[39m (pid=21943, ip=127.0.0.1, actor_id=96eb5048dfa308471bcaccc301000000, repr=<ray.rllib.evaluation.rollout_worker.RolloutWorker object at 0x105e46a50>)
           ^^^^^^^^^^^^^^^^^^^^^^^^^^^^^^^^^^^^
           ^^^^^^^^^^^^^^^^^^^^^^^^^^^^^^^
  File "/Users/jakejones/.virtualenvs/pettingzoo/lib/python3.11/site-packages/ray/rllib/evaluation/rollout_worker.py", line 404, in __init__
    check_env(self.env, self.config)
  File "/Users/jakejones/.virtualenvs/pettingzoo/lib/python3.11/site-packages/ray/rllib/utils/pre_checks/env.py", line 96, in check_env
    raise ValueError(
ValueError: Traceback (most recent call last):
  File "/Users/jakejones/.virtualenvs/pettingzoo/lib/python3.11/site-packages/ray/rllib/utils/pre_checks/env.py", line 81, in check_env
    check_multiagent_environments(env)
  File "/Users/jakejones/.virtualenvs/pettingzoo/lib/python3.11/site-packages/ray/rllib/utils/pre_checks/env.py", line 320, in check_multiagent_environments
    _check_if_element_multi_agent_dict(env, reset_obs, "reset()")
  File "/Users/jakejones/.virtualenvs/pettingzoo/lib/python3.11/site-packages/ray/rllib/utils/pre_checks/env.py", line 785, in _check_if_element_multi_agent_dict
    raise ValueError(error)
ValueError: The element returned by reset() has agent_ids that are not the names of the agents in the env. 
Agent_ids in this MultiAgentDict: ['player_0', 'player_1']
Agent_ids in this env:[]. You likely need to add the private attribute `_agent_ids` to your env, which is a set containing the ids of agents supported by your env.

The above error has been found in your environment! We've added a module for checking your custom environments. It may cause your experiment to fail if your environment is not set up correctly. You can disable this behavior via calling `config.environment(disable_env_checking=True)`. You can run the environment checking module standalone by calling ray.rllib.utils.check_env([your env]).

During handling of the above exception, another exception occurred:

[36mray::PPO.__init__()[39m (pid=21935, ip=127.0.0.1, actor_id=9512c01709e66983e0ddaa4e01000000, repr=PPO)
           ^^^^^^^^^^^^^^^^^^^^^^^^^^^^^^^^^^^^
           ^^^^^^^^^^^^^^^^^^^^^^^^^^^^^^^
  File "/Users/jakejones/.virtualenvs/pettingzoo/lib/python3.11/site-packages/ray/rllib/algorithms/algorithm.py", line 517, in __init__
    super().__init__(
  File "/Users/jakejones/.virtualenvs/pettingzoo/lib/python3.11/site-packages/ray/tune/trainable/trainable.py", line 185, in __init__
    self.setup(copy.deepcopy(self.config))
           ^^^^^^^^^^^^^^^^^^^^^^^^^^^^^^^
  File "/Users/jakejones/.virtualenvs/pettingzoo/lib/python3.11/site-packages/ray/rllib/algorithms/algorithm.py", line 639, in setup
    self.workers = WorkerSet(
                   ^^^^^^^^^^
  File "/Users/jakejones/.virtualenvs/pettingzoo/lib/python3.11/site-packages/ray/rllib/evaluation/worker_set.py", line 179, in __init__
    raise e.args[0].args[2]
ValueError: Traceback (most recent call last):
  File "/Users/jakejones/.virtualenvs/pettingzoo/lib/python3.11/site-packages/ray/rllib/utils/pre_checks/env.py", line 81, in check_env
    check_multiagent_environments(env)
  File "/Users/jakejones/.virtualenvs/pettingzoo/lib/python3.11/site-packages/ray/rllib/utils/pre_checks/env.py", line 320, in check_multiagent_environments
    _check_if_element_multi_agent_dict(env, reset_obs, "reset()")
  File "/Users/jakejones/.virtualenvs/pettingzoo/lib/python3.11/site-packages/ray/rllib/utils/pre_checks/env.py", line 785, in _check_if_element_multi_agent_dict
    raise ValueError(error)
ValueError: The element returned by reset() has agent_ids that are not the names of the agents in the env. 
Agent_ids in this MultiAgentDict: ['player_0', 'player_1']
Agent_ids in this env:[]. You likely need to add the private attribute `_agent_ids` to your env, which is a set containing the ids of agents supported by your env.

The above error has been found in your environment! We've added a module for checking your custom environments. It may cause your experiment to fail if your environment is not set up correctly. You can disable this behavior via calling `config.environment(disable_env_checking=True)`. You can run the environment checking module standalone by calling ray.rllib.utils.check_env([your env]).
